Workbook
Name PivotData: #REF!

Sheet 5 Year Supply Plan
D1: =(D2-C2)/C2 -> 0.11337298 | E1: =(E2-D2)/D2 -> 0.075186644 | F1: =(F2-E2)/E2 -> 0.074465916 | G1: =(G2-F2)/F2 -> 0.071498919
C2: =SUBTOTAL(9,C4:C46) -> 27062167 | D2: =SUBTOTAL(9,D4:D46) -> 30130285 | E2: =SUBTOTAL(9,E4:E46) -> 32395680 | F2: =SUBTOTAL(9,F4:F46) -> 34808054 | G2: =SUBTOTAL(9,G4:G46) -> 37296792 | H2: =SUBTOTAL(9,H4:H50) -> 2827759.9 | I2: =SUBTOTAL(9,I4:I50) -> 3335532 | J2: =SUBTOTAL(9,J4:J50) -> 2770654.5 | K2: =SUBTOTAL(9,K4:K50) -> 2577076 | L2: =SUBTOTAL(9,L4:L50) -> 1974451.5 | M2: =SUBTOTAL(9,M4:M50) -> 2551631.4 | N2: =SUBTOTAL(9,N4:N50) -> 2511649.7 | O2: =SUBTOTAL(9,O4:O50) -> 2508560.7 | ... BN2: =SUBTOTAL(9,BN4:BN50) -> 3268366.5
A3: Brands | B3: Source Plant | C3: FY26 | D3: FY27 | E3: FY28 | F3: FY29 | G3: FY30 | H3: Aug FY26 | I3: Sep FY26 | J3: Oct FY26 | K3: Nov FY26 | L3: Dec FY26 | M3: Jan FY26 | N3: Feb FY26 | O3: Mar FY26 | P3: Apr FY26 | Q3: May FY26 | R3: Jun FY26 | S3: Jul FY27 | T3: Aug FY27 | U3: Sep FY27 | V3: Oct FY27 | W3: Nov FY27 | X3: Dec FY27 | Y3: Jan FY27 | Z3: Feb FY27 | AA3: Mar FY27 | AB3: Apr FY27 | AC3: May FY27 | AD3: Jun FY27 | AE3: Jul FY28 | AF3: Aug FY28 | AG3: Sep FY28 | AH3: Oct FY28 | AI3: Nov FY28 | AJ3: Dec FY28 | AK3: Jan FY28 | AL3: Feb FY28 | AM3: Mar FY28 | AN3: Apr FY28 | AO3: May FY28 | AP3: Jun FY28 | AQ3: Jul FY29 | AR3: Aug FY29 | AS3: Sep FY29 | AT3: Oct FY29 | AU3: Nov FY29 | AV3: Dec FY29 | AW3: Jan FY29 | AX3: Feb FY29 | AY3: Mar FY29 | AZ3: Apr FY29 | BA3: May FY29 | BB3: Jun FY29 | BC3: Jul FY30 | BD3: Aug FY30 | BE3: Sep FY30 | BF3: Oct FY30 | BG3: Nov FY30 | BH3: Dec FY30 | BI3: Jan FY30 | BJ3: Feb FY30 | BK3: Mar FY30 | BL3: Apr FY30 | BM3: May FY30 | BN3: Jun FY30 | BO3: 5 Year Total
A4: ADROIT | B4: Salvarcar _ Juarez | C4: 115805 | D4: 123949 | E4: 129208 | F4: 135137 | G4: 143127.5 | H4: 15865 | I4: 18240 | J4: 15200 | K4: 9000 | L4: 5000 | M4: 8300 | N4: 8800 | O4: 8800 | P4: 8800 | Q4: 8800 | R4: 9000 | S4: 11721 | T4: 11524 | U4: 9955 | V4: 11390 | W4: 10564 | X4: 9420 | Y4: 7975 | Z4: 8515 | AA4: 10132 | AB4: 11221 | AC4: 11193 | AD4: 10339 | AE4: 12108 | AF4: 11898 | AG4: 10265 | AH4: 11759 | AI4: 10992 | AJ4: 9912 | AK4: 8446 | AL4: 8991 | AM4: 10629 | AN4: 11714 | AO4: 11687 | AP4: 10807 | AQ4: 12665 | AR4: 12450 | AS4: 10731 | AT4: 12304 | AU4: 11569 | AV4: 10529 | AW4: 9058 | AX4: 9521 | AY4: 11051 | AZ4: 12074 | BA4: 12041 | BB4: 11144 | BC4: 13080 | BD4: 12857 | BE4: 11068 | BF4: 12704 | BG4: 12009 | BH4: 11247 | BI4: 10155 | BJ4: 10566 | BK4: 12320 | BL4: 13890 | BM4: 11615.75 | BN4: 11615.75 | BO4: =SUM(H4:BN4) -> 647226.5
A5: AVANTI PLUS | B5: Salvarcar _ Juarez | C5: 5777104 | D5: 6478530 | E5: 7043533 | F5: 7653609 | G5: 8173129.8 | H5: 563176.73 | I5: 676363.35 | J5: 563719.94 | K5: 512615 | L5: 483484 | M5: 511792 | N5: 480492 | O5: 475448 | P5: 493730 | Q5: 540517 | R5: 475766 | S5: 547931 | T5: 559087 | U5: 524750 | V5: 554431 | W5: 525662 | X5: 564556 | Y5: 549100 | Z5: 493951 | AA5: 499570 | AB5: 536652 | AC5: 603150 | AD5: 519690 | AE5: 594140 | AF5: 606784 | AG5: 570808 | AH5: 602016 | AI5: 569110 | AJ5: 612307 | AK5: 596015 | AL5: 535369 | AM5: 541992 | AN5: 585661 | AO5: 661295 | AP5: 568036 | AQ5: 648742 | AR5: 663107 | AS5: 624999 | AT5: 658341 | AU5: 620716 | AV5: 668885 | AW5: 651687 | AX5: 588125 | AY5: 585427 | AZ5: 628285 | BA5: 708352 | BB5: 606943 | BC5: 692926 | BD5: 708698 | BE5: 668755 | BF5: 703607 | BG5: 662336 | BH5: 714368 | BI5: 698262 | BJ5: 660826 | BK5: 639327 | BL5: 659980 | BM5: 682022.38 | BN5: 682022.38 | BO5: =SUM(H5:BN5) -> 35125906
A6: BRITE TIP | B6: Salvarcar _ Juarez | C6: 1158714.2 | D6: 1247784 | E6: 1287016 | F6: 1340425 | G6: 1372095 | H6: 159148 | I6: 155459 | J6: 128367 | K6: 95000 | L6: 60740 | M6: 80000 | N6: 95000 | O6: 95000 | P6: 95000 | Q6: 95000 | R6: 100000 | S6: 108680 | T6: 108509 | U6: 105148 | V6: 108298 | W6: 101096 | X6: 106931 | Y6: 102807 | Z6: 89522 | AA6: 102972 | AB6: 116923 | AC6: 105515 | AD6: 91383 | AE6: 111801 | AF6: 111595 | AG6: 108097 | AH6: 111224 | AI6: 103927 | AJ6: 110058 | AK6: 105845 | AL6: 92075 | AM6: 106215 | AN6: 121018 | AO6: 109939 | AP6: 95222 | AQ6: 116566 | AR6: 116333 | AS6: 112657 | AT6: 115835 | AU6: 108309 | AV6: 114793 | AW6: 110416 | AX6: 96042 | AY6: 110495 | AZ6: 125741 | BA6: 114320 | BB6: 98918 | BC6: 121156 | BD6: 120888 | BE6: 117018 | BF6: 120215 | BG6: 112512 | BH6: 119373 | BI6: 114863 | BJ6: 99895 | BK6: 103796 | BL6: 115239 | BM6: 113570 | BN6: 113570 | BO6: =SUM(H6:BN6) -> 6406034
A7: BRITE TIP (MODIFIED) | B7: Salvarcar _ Juarez | C7: 20.018071 | D7: 0 | E7: 0 | F7: 0 | G7: 0 | H7: 3.340271 | I7: 5.309954 | J7: 11.367846 | BO7: =SUM(H7:BN7) -> 20.018071
A8: BRITE TIP RADIANZ | B8: Salvarcar _ Juarez | C8: 3765 | D8: 5435 | E8: 5879 | F8: 6551 | G8: 7992.25 | H8: 550 | I8: 720 | J8: 600 | K8: 250 | L8: 150 | M8: 245 | N8: 250 | O8: 250 | P8: 250 | Q8: 250 | R8: 250 | S8: 459 | T8: 499 | U8: 440 | V8: 777 | W8: 771 | X8: 792 | Y8: 288 | Z8: 271 | AA8: 278 | AB8: 284 | AC8: 292 | AD8: 284 | AE8: 473 | AF8: 512 | AG8: 450 | AH8: 872 | AI8: 875 | AJ8: 900 | AK8: 308 | AL8: 285 | AM8: 293 | AN8: 300 | AO8: 308 | AP8: 303 | AQ8: 570 | AR8: 636 | AS8: 560 | AT8: 950 | AU8: 941 | AV8: 969 | AW8: 328 | AX8: 307 | AY8: 315 | AZ8: 321 | BA8: 331 | BB8: 323 | BC8: 651 | BD8: 737 | BE8: 647 | BF8: 1065 | BG8: 1054 | BH8: 1086 | BI8: 347 | BJ8: 295 | BK8: 286 | BL8: 445 | BM8: 689.625 | BN8: 689.625 | BO8: =SUM(H8:BN8) -> 29622.25
A9: CATH EXT | B9: Salvarcar _ Juarez | C9: 11101.771 | D9: 13562 | E9: 14178 | F9: 14871 | G9: 15649.75 | H9: 1352.0989 | I9: 1666.8413 | J9: 1382.8309 | K9: 900 | L9: 500 | M9: 800 | N9: 900 | O9: 900 | P9: 900 | Q9: 900 | R9: 900 | S9: 1241 | T9: 1116 | U9: 1121 | V9: 1177 | W9: 1105 | X9: 1120 | Y9: 1154 | Z9: 1057 | AA9: 1077 | AB9: 1101 | AC9: 1226 | AD9: 1067 | AE9: 1298 | AF9: 1169 | AG9: 1171 | AH9: 1231 | AI9: 1155 | AJ9: 1173 | AK9: 1206 | AL9: 1105 | AM9: 1126 | AN9: 1151 | AO9: 1280 | AP9: 1113 | AQ9: 1357 | AR9: 1221 | AS9: 1223 | AT9: 1285 | AU9: 1207 | AV9: 1226 | AW9: 1264 | AX9: 1163 | AY9: 1185 | AZ9: 1212 | BA9: 1351 | BB9: 1177 | BC9: 1429 | BD9: 1290 | BE9: 1289 | BF9: 1355 | BG9: 1275 | BH9: 1296 | BI9: 1345 | BJ9: 1221 | BK9: 1236 | BL9: 1337 | BM9: 1288.375 | BN9: 1288.375 | BO9: =SUM(H9:BN9) -> 69362.521
A10: CORPACK | B10: Salvarcar _ Juarez | C10: 28948.02 | D10: 1133 | E10: 1222 | F10: 1315 | G10: 11279.5 | H10: 876.79425 | I10: 1271.276 | J10: 1112.9498 | K10: 4000 | L10: 4176 | M10: 3757 | N10: 4000 | O10: 4000 | P10: 4000 | Q10: 1500 | R10: 254 | S10: 103 | T10: 99 | U10: 91 | V10: 92 | W10: 93 | X10: 102 | Y10: 94 | Z10: 83 | AA10: 89 | AB10: 102 | AC10: 99 | AD10: 86 | AE10: 110 | AF10: 107 | AG10: 99 | AH10: 99 | AI10: 100 | AJ10: 111 | AK10: 101 | AL10: 90 | AM10: 96 | AN10: 111 | AO10: 105 | AP10: 93 | AQ10: 118 | AR10: 116 | AS10: 106 | AT10: 107 | AU10: 107 | AV10: 119 | AW10: 109 | AX10: 96 | AY10: 104 | AZ10: 119 | BA10: 114 | BB10: 100 | BC10: 128 | BD10: 124 | BE10: 115 | BF10: 115 | BG10: 116 | BH10: 128 | BI10: 119 | BJ10: 824 | BK10: 2997 | BL10: 5479 | BM10: 567.25 | BN10: 567.25 | BO10: =SUM(H10:BN10) -> 43897.52
A11: CORPACK (MODIFIED) | B11: Salvarcar _ Juarez | C11: 3875.2002 | D11: 0 | E11: 0 | F11: 0 | G11: 926 | H11: 154.09992 | I11: 401.9538 | J11: 325.14648 | K11: 400 | L11: 507 | M11: 493 | N11: 450 | O11: 400 | P11: 442 | Q11: 302 | BJ11: 86 | BK11: 305 | BL11: 535 | BO11: =SUM(H11:BN11) -> 4801.2002
A12: ENROUTE | B12: Salvarcar _ Juarez | C12: 29805 | D12: 36155 | E12: 36155 | F12: 18120 | G12: 0 | H12: 2005 | I12: 1700 | J12: 2100 | K12: 3200 | L12: 2200 | M12: 3200 | N12: 3200 | O12: 2800 | P12: 3150 | Q12: 3050 | R12: 3200 | S12: 2985 | T12: 2950 | U12: 3000 | V12: 2950 | W12: 2850 | X12: 3385 | Y12: 2750 | Z12: 2535 | AA12: 3350 | AB12: 3150 | AC12: 3050 | AD12: 3200 | AE12: 2985 | AF12: 2950 | AG12: 3000 | AH12: 2950 | AI12: 2850 | AJ12: 3385 | AK12: 2750 | AL12: 2535 | AM12: 3350 | AN12: 3150 | AO12: 3050 | AP12: 3200 | AQ12: 2985 | AR12: 2950 | AS12: 3000 | AT12: 2950 | AU12: 2850 | AV12: 3385 | AW12: 2832.5 | AX12: 2611.05 | AY12: 3450.5 | AZ12: 3244.5 | BA12: 3141.5 | BB12: 3296 | BC12: 3074.55 | BD12: 3038.5 | BE12: 3090 | BF12: 3038.5 | BG12: 2935.5 | BH12: 3486.55 | BI12: 2917.475 | BJ12: 2689.3815 | BK12: 3554.015 | BL12: 3341.835 | BM12: 3235.745 | BN12: 3394.88 | BO12: =SUM(H12:BN12) -> 176607.98
A13: EXOSEAL | B13: Salvarcar _ Juarez | C13: 604836 | D13: 604358 | E13: 642493 | F13: 733127 | G13: 791675.25 | H13: 76000 | I13: 97400 | J13: 48000 | K13: 55000 | L13: 30000 | M13: 50000 | N13: 50000 | O13: 48000 | P13: 48000 | Q13: 52878 | R13: 49558 | S13: 54451 | T13: 53967 | U13: 46098 | V13: 46587 | W13: 47626 | X13: 55789 | Y13: 54512 | Z13: 48432 | AA13: 44859 | AB13: 46681 | AC13: 54375 | AD13: 50981 | AE13: 55989 | AF13: 55484 | AG13: 47370 | AH13: 47842 | AI13: 48436 | AJ13: 55595 | AK13: 54481 | AL13: 50631 | AM13: 50121 | AN13: 53908 | AO13: 63298 | AP13: 59338 | AQ13: 65056 | AR13: 64540 | AS13: 55057 | AT13: 55360 | AU13: 56114 | AV13: 64641 | AW13: 63573 | AX13: 58381 | AY13: 55954 | AZ13: 59317 | BA13: 69748 | BB13: 65386 | BC13: 71647 | BD13: 71096 | BE13: 60616 | BF13: 60838 | BG13: 61704 | BH13: 71006 | BI13: 71662 | BJ13: 67328 | BK13: 61799 | BL13: 62467 | BM13: 65756.125 | BN13: 65756.125 | BO13: =SUM(H13:BN13) -> 3376489.2
A14: FRONTRUNNER | B14: Salvarcar _ Juarez | C14: 0 | D14: 0 | E14: 0 | F14: 0 | G14: 0 | BO14: =SUM(H14:BN14) -> 0
A15: HIGH FLOW | B15: Salvarcar _ Juarez | C15: 2306.2685 | D15: 5488 | E15: 5906 | F15: 6341 | G15: 6772.25 | H15: 182.23647 | I15: 79.16198 | J15: 200.87009 | K15: 200 | L15: 200 | M15: 200 | N15: 200 | O15: 200 | P15: 200 | Q15: 200 | R15: 444 | S15: 516 | T15: 432 | U15: 420 | V15: 504 | W15: 461 | X15: 441 | Y15: 443 | Z15: 453 | AA15: 445 | AB15: 441 | AC15: 455 | AD15: 477 | AE15: 557 | AF15: 464 | AG15: 451 | AH15: 544 | AI15: 495 | AJ15: 477 | AK15: 478 | AL15: 488 | AM15: 480 | AN15: 473 | AO15: 488 | AP15: 511 | AQ15: 598 | AR15: 498 | AS15: 485 | AT15: 583 | AU15: 531 | AV15: 509 | AW15: 513 | AX15: 524 | AY15: 514 | AZ15: 509 | BA15: 526 | BB15: 551 | BC15: 642 | BD15: 538 | BE15: 522 | BF15: 628 | BG15: 573 | BH15: 549 | BI15: 552 | BJ15: 563 | BK15: 548 | BL15: 539 | BM15: 559.125 | BN15: 559.125 | BO15: =SUM(H15:BN15) -> 26813.519
A16: INCRAFT | B16: Salvarcar _ Juarez | C16: 1752 | D16: 0 | E16: 0 | F16: 0 | G16: 320 | H16: 458 | I16: 494 | J16: 400 | K16: 400 | BK16: 94 | BL16: 226 | BO16: =SUM(H16:BN16) -> 2072
A17: INFINITI | B17: Salvarcar _ Juarez | C17: 7064892.1 | D17: 7762066 | E17: 8284703 | F17: 8792806 | G17: 9247260 | H17: 694365.12 | I17: 824439.75 | J17: 685154.25 | K17: 652395 | L17: 400000 | M17: 650268 | N17: 632412 | O17: 643687 | P17: 639404 | Q17: 625246 | R17: 617521 | S17: 672459 | T17: 677531 | U17: 627555 | V17: 630297 | W17: 626398 | X17: 698606 | Y17: 677121 | Z17: 601675 | AA17: 632136 | AB17: 667494 | AC17: 671189 | AD17: 579605 | AE17: 718100 | AF17: 724015 | AG17: 670852 | AH17: 671867 | AI17: 668727 | AJ17: 744642 | AK17: 721918 | AL17: 644990 | AM17: 673843 | AN17: 708550 | AO17: 719012 | AP17: 618187 | AQ17: 763295 | AR17: 769796 | AS17: 713937 | AT17: 712039 | AU17: 710212 | AV17: 789265 | AW17: 765615 | AX17: 690963 | AY17: 712113 | AZ17: 749275 | BA17: 763112 | BB17: 653184 | BC17: 805035 | BD17: 811507 | BE17: 753549 | BF17: 748725 | BG17: 748144 | BH17: 830099 | BI17: 797745 | BJ17: 701599 | BK17: 722492 | BL17: 799900 | BM17: 764232.5 | BN17: 764232.5 | BO17: =SUM(H17:BN17) -> 41151727
A18: INFINITI (MODIFIED) | B18: Salvarcar _ Juarez | C18: 68027.773 | D18: 31016 | E18: 33237 | F18: 35584 | G18: 38940.75 | H18: 8349.7031 | I18: 9697.071 | J18: 8112.9989 | K18: 7889 | L18: 8417 | M18: 8593 | N18: 7372 | O18: 5061 | P18: 2128 | Q18: 2407 | R18: 1 | S18: 2880 | T18: 2677 | U18: 2626 | V18: 2823 | W18: 2575 | X18: 2647 | Y18: 2410 | Z18: 2165 | AA18: 2311 | AB18: 2492 | AC18: 2553 | AD18: 2857 | AE18: 3088 | AF18: 2869 | AG18: 2815 | AH18: 3026 | AI18: 2760 | AJ18: 2838 | AK18: 2584 | AL18: 2320 | AM18: 2479 | AN18: 2671 | AO18: 2731 | AP18: 3056 | AQ18: 3304 | AR18: 3069 | AS18: 3012 | AT18: 3239 | AU18: 2955 | AV18: 3036 | AW18: 2764 | AX18: 2483 | AY18: 2652 | AZ18: 2859 | BA18: 2931 | BB18: 3280 | BC18: 3546 | BD18: 3293 | BE18: 3231 | BF18: 3475 | BG18: 3169 | BH18: 3259 | BI18: 2967 | BJ18: 896 | BK18: 3081 | BL18: 6181 | BM18: 2921.375 | BN18: 2921.375 | BO18: =SUM(H18:BN18) -> 206805.52
A19: INFINITI AMBI | B19: Salvarcar _ Juarez | C19: 24609.876 | D19: 31758 | E19: 34271 | F19: 36871 | G19: 39720 | H19: 796.9068 | I19: 1696.2485 | J19: 2390.7205 | K19: 760 | L19: 3189 | M19: 2366 | N19: 2994 | O19: 2037 | P19: 3502 | Q19: 2860 | R19: 2018 | S19: 2562 | T19: 3029 | U19: 2848 | V19: 2336 | W19: 2257 | X19: 3155 | Y19: 2915 | Z19: 2112 | AA19: 2117 | AB19: 3157 | AC19: 3090 | AD19: 2180 | AE19: 2767 | AF19: 3271 | AG19: 3076 | AH19: 2524 | AI19: 2437 | AJ19: 3407 | AK19: 3148 | AL19: 2281 | AM19: 2287 | AN19: 3409 | AO19: 3321 | AP19: 2343 | AQ19: 2974 | AR19: 3517 | AS19: 3307 | AT19: 2713 | AU19: 2619 | AV19: 3663 | AW19: 3384 | AX19: 2452 | AY19: 2459 | AZ19: 3666 | BA19: 3587 | BB19: 2530 | BC19: 3212 | BD19: 3798 | BE19: 3572 | BF19: 2929 | BG19: 2830 | BH19: 3955 | BI19: 3655 | BJ19: 2648 | BK19: 2657 | BL19: 3953 | BM19: 3255.5 | BN19: 3255.5 | BO19: =SUM(H19:BN19) -> 167229.88
A20: Long Sheath | B20: Salvarcar _ Juarez | C20: 14045.063 | D20: 14106 | E20: 14185 | F20: 14433 | G20: 15193.25 | H20: 3774.7332 | I20: 1296.9573 | J20: 1045.3728 | K20: 946 | L20: 905 | M20: 1062 | N20: 1039 | O20: 987 | P20: 928 | Q20: 1008 | R20: 1053 | S20: 1226 | T20: 1229 | U20: 1120 | V20: 1193 | W20: 1141 | X20: 1263 | Y20: 1255 | Z20: 1154 | AA20: 1140 | AB20: 1150 | AC20: 1182 | AD20: 1053 | AE20: 1229 | AF20: 1229 | AG20: 1123 | AH20: 1194 | AI20: 1141 | AJ20: 1265 | AK20: 1255 | AL20: 1152 | AM20: 1149 | AN20: 1173 | AO20: 1204 | AP20: 1071 | AQ20: 1256 | AR20: 1251 | AS20: 1144 | AT20: 1215 | AU20: 1162 | AV20: 1290 | AW20: 1279 | AX20: 1172 | AY20: 1167 | AZ20: 1190 | BA20: 1220 | BB20: 1087 | BC20: 1271 | BD20: 1271 | BE20: 1159 | BF20: 1231 | BG20: 1179 | BH20: 1308 | BI20: 1296 | BJ20: 1198 | BK20: 1303 | BL20: 1491 | BM20: 1243.125 | BN20: 1243.125 | BO20: =SUM(H20:BN20) -> 71962.313
A21: MULTIPACK | B21: Salvarcar _ Juarez | C21: 151837.65 | D21: 243628 | E21: 246482 | F21: 251273 | G21: 249518.75 | H21: 13099.21 | I21: 15268.168 | J21: 12325.276 | K21: 12321 | L21: 12221 | M21: 12114 | N21: 13025 | O21: 13076 | P21: 14895 | Q21: 15652 | R21: 17841 | S21: 20955 | T21: 19958 | U21: 17178 | V21: 18393 | W21: 19974 | X21: 24422 | Y21: 24013 | Z21: 21691 | AA21: 20212 | AB21: 18981 | AC21: 19871 | AD21: 17980 | AE21: 21165 | AF21: 20169 | AG21: 17387 | AH21: 18583 | AI21: 20147 | AJ21: 24588 | AK21: 24153 | AL21: 21817 | AM21: 20453 | AN21: 19401 | AO21: 20283 | AP21: 18336 | AQ21: 21616 | AR21: 20599 | AS21: 17778 | AT21: 18980 | AU21: 20556 | AV21: 25064 | AW21: 24609 | AX21: 22214 | AY21: 20822 | AZ21: 19756 | BA21: 20644 | BB21: 18635 | BC21: 22012 | BD21: 20984 | BE21: 18138 | BF21: 19331 | BG21: 20905 | BH21: 25449 | BI21: 24979 | BJ21: 22070 | BK21: 18515 | BL21: 14543 | BM21: 21296.375 | BN21: 21296.375 | BO21: =SUM(H21:BN21) -> 1142739.4
A22: MULTIPACK (MODIFIED) | B22: Salvarcar _ Juarez | C22: 84883.465 | D22: 37961 | E22: 40963 | F22: 44073 | G22: 60942.5 | H22: 10732.131 | I22: 11784.523 | J22: 9860.8105 | K22: 11325 | L22: 5876 | M22: 10311 | N22: 8748 | O22: 6588 | P22: 3875 | Q22: 3027 | R22: 2756 | S22: 3086 | T22: 3147 | U22: 2351 | V22: 2859 | W22: 2600 | X22: 3077 | Y22: 3817 | Z22: 3302 | AA22: 3550 | AB22: 3926 | AC22: 3269 | AD22: 2977 | AE22: 3333 | AF22: 3399 | AG22: 2539 | AH22: 3086 | AI22: 2808 | AJ22: 3324 | AK22: 4123 | AL22: 3566 | AM22: 3834 | AN22: 4236 | AO22: 3515 | AP22: 3200 | AQ22: 3583 | AR22: 3653 | AS22: 2729 | AT22: 3317 | AU22: 3019 | AV22: 3574 | AW22: 4431 | AX22: 3834 | AY22: 4123 | AZ22: 4557 | BA22: 3794 | BB22: 3459 | BC22: 3869 | BD22: 3944 | BE22: 2949 | BF22: 3584 | BG22: 3259 | BH22: 3859 | BI22: 4787 | BJ22: 5047 | BK22: 8349 | BL22: 12351 | BM22: 4472.25 | BN22: 4472.25 | BO22: =SUM(H22:BN22) -> 268822.96
A23: OPTEASE | B23: Salvarcar _ Juarez | C23: 22037 | D23: 24803 | E23: 25729 | F23: 27538 | G23: 26039 | H23: 2000 | I23: 2400 | J23: 2000 | K23: 1972 | L23: 1267 | M23: 2022 | N23: 2087 | O23: 2241 | P23: 2156 | Q23: 2035 | R23: 1857 | S23: 2213 | T23: 2367 | U23: 1885 | V23: 2061 | W23: 1779 | X23: 1866 | Y23: 1986 | Z23: 2201 | AA23: 2261 | AB23: 2194 | AC23: 2086 | AD23: 1904 | AE23: 2272 | AF23: 2429 | AG23: 1931 | AH23: 2105 | AI23: 1811 | AJ23: 1908 | AK23: 2032 | AL23: 2278 | AM23: 2361 | AN23: 2324 | AO23: 2234 | AP23: 2044 | AQ23: 2439 | AR23: 2605 | AS23: 2061 | AT23: 2242 | AU23: 1923 | AV23: 2034 | AW23: 2184 | AX23: 2419 | AY23: 2494 | AZ23: 2490 | BA23: 2422 | BB23: 2225 | BC23: 2655 | BD23: 2834 | BE23: 2230 | BF23: 2412 | BG23: 2069 | BH23: 1973 | BI23: 2007 | BJ23: 1902 | BK23: 1793 | BL23: 1859 | BM23: 2152.5 | BN23: 2152.5 | BO23: =SUM(H23:BN23) -> 126146
A24: OPTEASE RETRIEVAL CATHETER | B24: Salvarcar _ Juarez | C24: 18021 | D24: 25092 | E24: 27190 | F24: 30174 | G24: 30428.5 | K24: 2300 | L24: 1500 | M24: 2300 | N24: 2500 | O24: 2500 | P24: 2500 | Q24: 2500 | R24: 1921 | S24: 2160 | T24: 2436 | U24: 2199 | V24: 2170 | W24: 2074 | X24: 1867 | Y24: 1945 | Z24: 2288 | AA24: 2056 | AB24: 1775 | AC24: 2062 | AD24: 2060 | AE24: 2319 | AF24: 2622 | AG24: 2366 | AH24: 2336 | AI24: 2228 | AJ24: 2001 | AK24: 2089 | AL24: 2458 | AM24: 2236 | AN24: 1962 | AO24: 2287 | AP24: 2286 | AQ24: 2577 | AR24: 2923 | AS24: 2636 | AT24: 2602 | AU24: 2479 | AV24: 2221 | AW24: 2322 | AX24: 2764 | AY24: 2474 | AZ24: 2152 | BA24: 2509 | BB24: 2515 | BC24: 2835 | BD24: 3224 | BE24: 2904 | BF24: 2868 | BG24: 2728 | BH24: 2437 | BI24: 2171 | BJ24: 2175 | BK24: 2027 | BL24: 1926 | BM24: 2566.75 | BN24: 2566.75 | BO24: =SUM(H24:BN24) -> 130905.5
A25: OUTBACK ELITE | B25: Salvarcar _ Juarez | C25: 6000 | D25: 6324 | E25: 6205 | F25: 6021 | G25: 6301 | H25: 700 | I25: 960 | J25: 800 | K25: 463 | L25: 250 | M25: 463 | N25: 467 | O25: 472 | P25: 476 | Q25: 488 | R25: 461 | S25: 565 | T25: 570 | U25: 507 | V25: 553 | W25: 540 | X25: 576 | Y25: 547 | Z25: 510 | AA25: 513 | AB25: 507 | AC25: 482 | AD25: 454 | AE25: 558 | AF25: 561 | AG25: 494 | AH25: 543 | AI25: 531 | AJ25: 565 | AK25: 535 | AL25: 490 | AM25: 493 | AN25: 500 | AO25: 485 | AP25: 450 | AQ25: 534 | AR25: 530 | AS25: 468 | AT25: 510 | AU25: 506 | AV25: 557 | AW25: 531 | AX25: 489 | AY25: 493 | AZ25: 498 | BA25: 475 | BB25: 430 | BC25: 510 | BD25: 504 | BE25: 450 | BF25: 504 | BG25: 502 | BH25: 541 | BI25: 508 | BJ25: 503 | BK25: 588 | BL25: 666 | BM25: 512.5 | BN25: 512.5 | BO25: =SUM(H25:BN25) -> 30851
A26: PRECISE PRO | B26: Salvarcar _ Juarez | C26: 30244 | D26: 36926 | E26: 38188 | F26: 40584 | G26: 42785.75 | H26: 5195 | I26: 5760 | J26: 4800 | K26: 2049 | L26: 1047 | M26: 1823 | N26: 1774 | O26: 1927 | P26: 1984 | Q26: 1937 | R26: 1948 | S26: 3401 | T26: 3207 | U26: 2395 | V26: 3046 | W26: 3248 | X26: 3194 | Y26: 2946 | Z26: 3097 | AA26: 3153 | AB26: 3206 | AC26: 3008 | AD26: 3025 | AE26: 3536 | AF26: 3338 | AG26: 2493 | AH26: 3159 | AI26: 3366 | AJ26: 3310 | AK26: 2931 | AL26: 3134 | AM26: 3261 | AN26: 3309 | AO26: 3144 | AP26: 3207 | AQ26: 3755 | AR26: 3550 | AS26: 2667 | AT26: 3367 | AU26: 3565 | AV26: 3503 | AW26: 3133 | AX26: 3326 | AY26: 3464 | AZ26: 3513 | BA26: 3337 | BB26: 3404 | BC26: 3986 | BD26: 3764 | BE26: 2826 | BF26: 3553 | BG26: 3755 | BH26: 3758 | BI26: 3386 | BJ26: 3467 | BK26: 3578 | BL26: 3691 | BM26: 3510.875 | BN26: 3510.875 | BO26: =SUM(H26:BN26) -> 188727.75
A27: PRIMOPAC | B27: Salvarcar _ Juarez | C27: 3400.1328 | D27: 4927 | E27: 5323 | F27: 5611 | G27: 6568.25 | H27: 132.97655 | I27: 319.51758 | J27: 309.63867 | K27: 308 | L27: 147 | M27: 312 | N27: 423 | O27: 444 | P27: 366 | Q27: 329 | R27: 309 | S27: 375 | T27: 347 | U27: 313 | V27: 356 | W27: 443 | X27: 575 | Y27: 570 | Z27: 489 | AA27: 407 | AB27: 349 | AC27: 364 | AD27: 339 | AE27: 416 | AF27: 388 | AG27: 349 | AH27: 392 | AI27: 478 | AJ27: 611 | AK27: 602 | AL27: 517 | AM27: 442 | AN27: 385 | AO27: 385 | AP27: 358 | AQ27: 440 | AR27: 410 | AS27: 370 | AT27: 412 | AU27: 500 | AV27: 634 | AW27: 623 | AX27: 537 | AY27: 465 | AZ27: 414 | BA27: 418 | BB27: 388 | BC27: 476 | BD27: 447 | BE27: 403 | BF27: 445 | BG27: 532 | BH27: 669 | BI27: 655 | BJ27: 598 | BK27: 612 | BL27: 641 | BM27: 545.125 | BN27: 545.125 | BO27: =SUM(H27:BN27) -> 25829.383
A28: PROPAC | B28: Salvarcar _ Juarez | C28: 3535.9503 | D28: 4425 | E28: 4764 | F28: 5127 | G28: 5921.75 | H28: 278.74603 | I28: 98.868912 | J28: 142.33536 | K28: 425 | L28: 323 | M28: 411 | N28: 365 | O28: 396 | P28: 422 | Q28: 358 | R28: 316 | S28: 401 | T28: 390 | U28: 352 | V28: 360 | W28: 365 | X28: 397 | Y28: 364 | Z28: 323 | AA28: 351 | AB28: 396 | AC28: 385 | AD28: 341 | AE28: 433 | AF28: 420 | AG28: 379 | AH28: 389 | AI28: 392 | AJ28: 428 | AK28: 393 | AL28: 349 | AM28: 377 | AN28: 425 | AO28: 413 | AP28: 366 | AQ28: 464 | AR28: 451 | AS28: 407 | AT28: 416 | AU28: 420 | AV28: 460 | AW28: 421 | AX28: 373 | AY28: 408 | AZ28: 464 | BA28: 447 | BB28: 396 | BC28: 502 | BD28: 488 | BE28: 439 | BF28: 452 | BG28: 455 | BH28: 497 | BI28: 455 | BJ28: 411 | BK28: 522 | BL28: 771 | BM28: 464.875 | BN28: 464.875 | BO28: =SUM(H28:BN28) -> 23773.7
A29: PROPAC (MODIFIED) | B29: Salvarcar _ Juarez | C29: 6247.4258 | D29: 0 | E29: 0 | F29: 0 | G29: 0 | H29: 982.87946 | I29: 2807.3181 | J29: 2457.2283 | BO29: =SUM(H29:BN29) -> 6247.4258
A30: RAILWAY | B30: Salvarcar _ Juarez | C30: 0 | D30: 0 | E30: 0 | F30: 0 | G30: 0 | H30: 0 | I30: 0 | J30: 0 | K30: 0 | L30: 0 | M30: 0 | N30: 0 | O30: 0 | P30: 0 | Q30: 0 | R30: 0 | S30: 0 | T30: 0 | U30: 0 | V30: 0 | W30: 0 | X30: 0 | Y30: 0 | Z30: 0 | AA30: 0 | AB30: 0 | AC30: 0 | AD30: 0 | AE30: 0 | AF30: 0 | AG30: 0 | AH30: 0 | AI30: 0 | AJ30: 0 | AK30: 0 | AL30: 0 | AM30: 0 | AN30: 0 | AO30: 0 | AP30: 0 | AQ30: 0 | AR30: 0 | AS30: 0 | AT30: 0 | AU30: 0 | AV30: 0 | AW30: 0 | AX30: 0 | AY30: 0 | AZ30: 0 | BA30: 0 | BB30: 0 | BC30: 0 | BD30: 0 | BE30: 0 | BF30: 0 | BG30: 0 | BH30: 0 | BI30: 0 | BJ30: 0 | BK30: 0 | BL30: 0 | BM30: 0 | BN30: 0 | BO30: =SUM(H30:BN30) -> 0
A31: RAIN Sheath Transradial | B31: Salvarcar _ Juarez | C31: 288075.88 | D31: 326555 | E31: 342095 | F31: 360023 | G31: 380860.25 | H31: 35770.391 | I31: 42466.047 | J31: 35354.445 | K31: 21284 | L31: 13934 | M31: 23171 | N31: 23508 | O31: 23891 | P31: 22797 | Q31: 23158 | R31: 22742 | S31: 27835 | T31: 27568 | U31: 24804 | V31: 26653 | W31: 26560 | X31: 29468 | Y31: 28679 | Z31: 27692 | AA31: 29657 | AB31: 28496 | AC31: 25340 | AD31: 23803 | AE31: 29177 | AF31: 28870 | AG31: 25987 | AH31: 27883 | AI31: 27797 | AJ31: 30823 | AK31: 29961 | AL31: 28913 | AM31: 31082 | AN31: 30018 | AO31: 26612 | AP31: 24972 | AQ31: 30636 | AR31: 30294 | AS31: 27275 | AT31: 29244 | AU31: 29158 | AV31: 32324 | AW31: 31404 | AX31: 30304 | AY31: 32720 | AZ31: 31912 | BA31: 28262 | BB31: 26490 | BC31: 32523 | BD31: 32142 | BE31: 28948 | BF31: 31013 | BG31: 30927 | BH31: 34262 | BI31: 33081 | BJ31: 30659 | BK31: 31337 | BL31: 32876 | BM31: 31546.125 | BN31: 31546.125 | BO31: =SUM(H31:BN31) -> 1697609.1
A32: S.M.A.R.T. RADIANZ | B32: Salvarcar _ Juarez | C32: 3386.6963 | D32: 3474 | E32: 3599 | F32: 3761 | G32: 3759.25 | H32: 588.69629 | I32: 720 | J32: 600 | K32: 192 | L32: 153 | M32: 183 | N32: 185 | O32: 187 | P32: 189 | Q32: 193 | R32: 196 | S32: 312 | T32: 304 | U32: 269 | V32: 310 | W32: 288 | X32: 287 | Y32: 278 | Z32: 273 | AA32: 280 | AB32: 291 | AC32: 302 | AD32: 280 | AE32: 322 | AF32: 314 | AG32: 280 | AH32: 321 | AI32: 299 | AJ32: 298 | AK32: 289 | AL32: 284 | AM32: 288 | AN32: 302 | AO32: 313 | AP32: 289 | AQ32: 334 | AR32: 326 | AS32: 289 | AT32: 335 | AU32: 308 | AV32: 308 | AW32: 300 | AX32: 298 | AY32: 306 | AZ32: 320 | BA32: 332 | BB32: 305 | BC32: 355 | BD32: 345 | BE32: 306 | BF32: 352 | BG32: 328 | BH32: 326 | BI32: 309 | BJ32: 282 | BK32: 261 | BL32: 268 | BM32: 313.625 | BN32: 313.625 | BO32: =SUM(H32:BN32) -> 17979.946
A33: SMART | B33: Salvarcar _ Juarez | C33: 51478.551 | D33: 57677 | E33: 59590 | F33: 61752 | G33: 63232.5 | H33: 6467.5508 | I33: 8160 | J33: 6800 | K33: 3872 | L33: 1460 | M33: 3655 | N33: 3840 | O33: 3855 | P33: 4119 | Q33: 4826 | R33: 4424 | S33: 5046 | T33: 5080 | U33: 4512 | V33: 5040 | W33: 4784 | X33: 4892 | Y33: 4587 | Z33: 4466 | AA33: 4695 | AB33: 4966 | AC33: 5013 | AD33: 4596 | AE33: 5238 | AF33: 5273 | AG33: 4682 | AH33: 5232 | AI33: 4960 | AJ33: 5071 | AK33: 4763 | AL33: 4610 | AM33: 4802 | AN33: 5084 | AO33: 5150 | AP33: 4725 | AQ33: 5386 | AR33: 5421 | AS33: 4814 | AT33: 5380 | AU33: 5096 | AV33: 5216 | AW33: 4912 | AX33: 4792 | AY33: 5044 | AZ33: 5347 | BA33: 5395 | BB33: 4949 | BC33: 5639 | BD33: 5673 | BE33: 5039 | BF33: 5629 | BG33: 5331 | BH33: 5454 | BI33: 5140 | BJ33: 4862 | BK33: 4882 | BL33: 5081 | BM33: 5251.25 | BN33: 5251.25 | BO33: =SUM(H33:BN33) -> 293730.05
A34: SUPER TORQUE MARKER BANDS | B34: Salvarcar _ Juarez | C34: 65208 | D34: 75010 | E34: 76158 | F34: 82135 | G34: 89737 | H34: 6000 | I34: 7200 | J34: 6000 | K34: 4284 | L34: 6330 | M34: 6699 | N34: 6215 | O34: 6389 | P34: 5901 | Q34: 5223 | R34: 4967 | S34: 6112 | T34: 5536 | U34: 5890 | V34: 6977 | W34: 7012 | X34: 7213 | Y34: 6979 | Z34: 6443 | AA34: 6628 | AB34: 6097 | AC34: 5169 | AD34: 4954 | AE34: 6068 | AF34: 5512 | AG34: 5861 | AH34: 7024 | AI34: 7053 | AJ34: 7258 | AK34: 6988 | AL34: 6493 | AM34: 6751 | AN34: 6248 | AO34: 5551 | AP34: 5351 | AQ34: 6548 | AR34: 5945 | AS34: 6326 | AT34: 7610 | AU34: 7636 | AV34: 7858 | AW34: 7562 | AX34: 7036 | AY34: 7251 | AZ34: 6668 | BA34: 5950 | BB34: 5745 | BC34: 7071 | BD34: 6407 | BE34: 6833 | BF34: 8225 | BG34: 8255 | BH34: 8497 | BI34: 8053 | BJ34: 7336 | BK34: 7082 | BL34: 6806 | BM34: 7586 | BN34: 7586 | BO34: =SUM(H34:BN34) -> 388248
A35: SUPERTORQUE | B35: Salvarcar _ Juarez | C35: 457352 | D35: 554019 | E35: 599494 | F35: 630082 | G35: 679653 | H35: 40000.001 | I35: 48480 | J35: 40400 | K35: 43923 | L35: 29824 | M35: 45200 | N35: 40610 | O35: 43590 | P35: 49005 | Q35: 42891 | R35: 33429 | S35: 44901 | T35: 43437 | U35: 42081 | V35: 47014 | W35: 45695 | X35: 51602 | Y35: 50623 | Z35: 45183 | AA35: 46193 | AB35: 53659 | AC35: 46879 | AD35: 36752 | AE35: 49318 | AF35: 47672 | AG35: 46139 | AH35: 50972 | AI35: 49658 | AJ35: 56104 | AK35: 54915 | AL35: 48840 | AM35: 50041 | AN35: 58115 | AO35: 49155 | AP35: 38565 | AQ35: 51745 | AR35: 50006 | AS35: 48390 | AT35: 53358 | AU35: 52005 | AV35: 58755 | AW35: 57487 | AX35: 51092 | AY35: 52393 | AZ35: 61694 | BA35: 52098 | BB35: 41059 | BC35: 55077 | BD35: 53243 | BE35: 51565 | BF35: 56643 | BG35: 55261 | BH35: 62482 | BI35: 61149 | BJ35: 54221 | BK35: 54952 | BL35: 62681 | BM35: 56189.5 | BN35: 56189.5 | BO35: =SUM(H35:BN35) -> 2920600
A36: SUPERTORQUE (MODIFIED) | B36: Salvarcar _ Juarez | C36: 0 | D36: 0 | E36: 0 | F36: 0 | G36: 0 | H36: 0 | I36: 0 | J36: 0 | K36: 0 | L36: 0 | M36: 0 | N36: 0 | O36: 0 | P36: 0 | Q36: 0 | R36: 0 | S36: 0 | T36: 0 | U36: 0 | V36: 0 | W36: 0 | X36: 0 | Y36: 0 | Z36: 0 | AA36: 0 | AB36: 0 | AC36: 0 | AD36: 0 | AE36: 0 | AF36: 0 | AG36: 0 | AH36: 0 | AI36: 0 | AJ36: 0 | AK36: 0 | AL36: 0 | AM36: 0 | AN36: 0 | AO36: 0 | AP36: 0 | AQ36: 0 | AR36: 0 | AS36: 0 | AT36: 0 | AU36: 0 | AV36: 0 | AW36: 0 | AX36: 0 | AY36: 0 | AZ36: 0 | BA36: 0 | BB36: 0 | BC36: 0 | BD36: 0 | BE36: 0 | BF36: 0 | BG36: 0 | BH36: 0 | BI36: 0 | BJ36: 0 | BK36: 0 | BL36: 0 | BM36: 0 | BN36: 0 | BO36: =SUM(H36:BN36) -> 0
A37: SUPERTORQUE PLUS | B37: Salvarcar _ Juarez | C37: 2777117 | D37: 3239102 | E37: 3299183 | F37: 3321473 | G37: 3551499 | H37: 272655.75 | I37: 347864.88 | J37: 289887.38 | K37: 213242 | L37: 142365 | M37: 259108 | N37: 262748 | O37: 267131 | P37: 261281 | Q37: 235563 | R37: 225271 | S37: 267417 | T37: 262765 | U37: 249965 | V37: 273900 | W37: 286162 | X37: 321354 | Y37: 296819 | Z37: 268018 | AA37: 273239 | AB37: 268199 | AC37: 240946 | AD37: 230318 | AE37: 273429 | AF37: 268682 | AG37: 255680 | AH37: 280032 | AI37: 292479 | AJ37: 328390 | AK37: 303409 | AL37: 273817 | AM37: 277909 | AN37: 270924 | AO37: 242486 | AP37: 231946 | AQ37: 276074 | AR37: 270915 | AS37: 258298 | AT37: 282630 | AU37: 296002 | AV37: 333041 | AW37: 307502 | AX37: 277173 | AY37: 279507 | AZ37: 270460 | BA37: 239963 | BB37: 229908 | BC37: 275018 | BD37: 269247 | BE37: 258031 | BF37: 281553 | BG37: 296398 | BH37: 335247 | BI37: 318415 | BJ37: 300240 | BK37: 307169 | BL37: 318606 | BM37: 295787.5 | BN37: 295787.5 | BO37: =SUM(H37:BN37) -> 16188374
A38: SUPERTORQUE PLUS (MODIFIED) | B38: Salvarcar _ Juarez | C38: 46028.347 | D38: 11640 | E38: 12455 | F38: 13304 | G38: 24219.25 | H38: 7883.3086 | I38: 8516.9609 | J38: 7195.0776 | K38: 4588 | L38: 2121 | M38: 4792 | N38: 4971 | O38: 2867 | P38: 999 | Q38: 1102 | R38: 993 | S38: 1111 | T38: 994 | U38: 822 | V38: 1024 | W38: 918 | X38: 951 | Y38: 885 | Z38: 805 | AA38: 858 | AB38: 1028 | AC38: 1181 | AD38: 1063 | AE38: 1191 | AF38: 1063 | AG38: 880 | AH38: 1097 | AI38: 983 | AJ38: 1018 | AK38: 948 | AL38: 862 | AM38: 918 | AN38: 1099 | AO38: 1261 | AP38: 1135 | AQ38: 1269 | AR38: 1135 | AS38: 940 | AT38: 1170 | AU38: 1049 | AV38: 1086 | AW38: 1012 | AX38: 919 | AY38: 980 | AZ38: 1176 | BA38: 1351 | BB38: 1217 | BC38: 1361 | BD38: 1217 | BE38: 1007 | BF38: 1254 | BG38: 1125 | BH38: 1165 | BI38: 1025 | BJ38: 1784 | BK38: 4220 | BL38: 6862 | BM38: 1599.625 | BN38: 1599.625 | BO38: =SUM(H38:BN38) -> 107646.6
A39: TEMPO | B39: Salvarcar _ Juarez | C39: 4692257 | D39: 5434562 | E39: 6096962 | F39: 6840852 | G39: 7544905.5 | H39: 425250 | I39: 504000 | J39: 420000 | K39: 490443 | L39: 441110 | M39: 434547 | N39: 414129 | O39: 410388 | P39: 391390 | Q39: 395135 | R39: 365865 | S39: 434544 | T39: 499809 | U39: 466382 | V39: 447917 | W39: 435548 | X39: 476535 | Y39: 472977 | Z39: 447950 | AA39: 455025 | AB39: 438996 | AC39: 445982 | AD39: 412897 | AE39: 490876 | AF39: 564433 | AG39: 521847 | AH39: 497228 | AI39: 484082 | AJ39: 530482 | AK39: 527062 | AL39: 499446 | AM39: 510308 | AN39: 496225 | AO39: 506261 | AP39: 468712 | AQ39: 557595 | AR39: 641149 | AS39: 588142 | AT39: 556544 | AU39: 542347 | AV39: 595164 | AW39: 592224 | AX39: 565427 | AY39: 567356 | AZ39: 551251 | BA39: 562498 | BB39: 521155 | BC39: 619412 | BD39: 713133 | BE39: 655035 | BF39: 620422 | BG39: 604259 | BH39: 662615 | BI39: 644924 | BJ39: 627794 | BK39: 572476 | BL39: 549671 | BM39: 637582.25 | BN39: 637582.25 | BO39: =SUM(H39:BN39) -> 30609538
A40: TEMPO (MODIFIED) | B40: Salvarcar _ Juarez | C40: 157593 | D40: 22413 | E40: 24446 | F40: 26141 | G40: 55895 | H40: 21541.398 | I40: 25542.451 | J40: 21324.15 | K40: 24848 | L40: 18726 | M40: 18505 | N40: 14542 | O40: 6980 | P40: 2185 | Q40: 1820 | R40: 1579 | S40: 2025 | T40: 1971 | U40: 1791 | V40: 1811 | W40: 1823 | X40: 2015 | Y40: 1857 | Z40: 1625 | AA40: 1753 | AB40: 2017 | AC40: 1994 | AD40: 1731 | AE40: 2220 | AF40: 2160 | AG40: 1964 | AH40: 1984 | AI40: 2000 | AJ40: 2208 | AK40: 2037 | AL40: 1780 | AM40: 1922 | AN40: 2196 | AO40: 2127 | AP40: 1848 | AQ40: 2369 | AR40: 2305 | AS40: 2096 | AT40: 2118 | AU40: 2133 | AV40: 2357 | AW40: 2172 | AX40: 1902 | AY40: 2060 | AZ40: 2378 | BA40: 2276 | BB40: 1975 | BC40: 2535 | BD40: 2465 | BE40: 2241 | BF40: 2265 | BG40: 2281 | BH40: 2521 | BI40: 2324 | BJ40: 4487 | BK40: 10956 | BL40: 16435 | BM40: 3692.5 | BN40: 3692.5 | BO40: =SUM(H40:BN40) -> 286488
...

Sheet JZ_BRAND SPLITS
E1: =SUBTOTAL(9,E3:E77) -> 44 | G1: =SUBTOTAL(9,G3:G77) -> 2731168.9 | I1: =SUBTOTAL(9,I3:I77) -> 3230932 | K1: =SUBTOTAL(9,K3:K77) -> 2656628.5 | M1: =SUBTOTAL(9,M3:M77) -> 2471132 | O1: =SUBTOTAL(9,O3:O77) -> 1861369.5 | Q1: =SUBTOTAL(9,Q3:Q77) -> 2435563.4 | S1: =SUBTOTAL(9,S3:S77) -> 2387394.7 | U1: =SUBTOTAL(9,U3:U77) -> 2393580.7 | W1: =SUBTOTAL(9,W3:W77) -> 2364410.5 | Y1: =SUBTOTAL(9,Y3:Y77) -> 2362764.2 | AA1: =SUBTOTAL(9,AA3:AA77) -> 2226399.9 | AC1: =SUBTOTAL(9,AC3:AC77) -> 2542854.8 | AE1: =SUBTOTAL(9,AE3:AE77) -> 2613314.5 | AG1: =SUBTOTAL(9,AG3:AG77) -> 2431478 | AI1: =SUBTOTAL(9,AI3:AI77) -> 2505366 | AK1: =SUBTOTAL(9,AK3:AK77) -> 2455871.5 | AM1: =SUBTOTAL(9,AM3:AM77) -> 2707471.4 | AO1: =SUBTOTAL(9,AO3:AO77) -> 2630514.7 | AQ1: =SUBTOTAL(9,AQ3:AQ77) -> 2393385.7 | AS1: =SUBTOTAL(9,AS3:AS77) -> 2480216.5 | AU1: =SUBTOTAL(9,AU3:AU77) -> 2562350.2 | AW1: =SUBTOTAL(9,AW3:AW77) -> 2571185.9 | AY1: =SUBTOTAL(9,AY3:AY77) -> 2303372.8 | BA1: =SUBTOTAL(9,BA3:BA77) -> 2732965.1 | BC1: =SUBTOTAL(9,BC3:BC77) -> 2814780.6 | BE1: =SUBTOTAL(9,BE3:BE77) -> 2614920.4 | BG1: =SUBTOTAL(9,BG3:BG77) -> 2683646.4 | BI1: =SUBTOTAL(9,BI3:BI77) -> 2629877.4 | BK1: =SUBTOTAL(9,BK3:BK77) -> 2897943.7 | BM1: =SUBTOTAL(9,BM3:BM77) -> 2818210.7 | BO1: =SUBTOTAL(9,BO3:BO77) -> 2571422.5 | BQ1: =SUBTOTAL(9,BQ3:BQ77) -> 2666204.2 | BS1: =SUBTOTAL(9,BS3:BS77) -> 2759048.9 | BU1: =SUBTOTAL(9,BU3:BU77) -> 2785540.8 | BW1: =SUBTOTAL(9,BW3:BW77) -> 2490229.1 | BY1: =SUBTOTAL(9,BY3:BY77) -> 2951446 | CA1: =SUBTOTAL(9,CA3:CA77) -> 3046042.5 | CC1: =SUBTOTAL(9,CC3:CC77) -> 2825186.4 | CE1: =SUBTOTAL(9,CE3:CE77) -> 2886742.4 | CG1: =SUBTOTAL(9,CG3:CG77) -> 2829659.7 | CI1: =SUBTOTAL(9,CI3:CI77) -> 3118395.7 | CK1: =SUBTOTAL(9,CK3:CK77) -> 3037025 | CM1: =SUBTOTAL(9,CM3:CM77) -> 2786782.2 | CO1: =SUBTOTAL(9,CO3:CO77) -> 2849945.4 | CQ1: =SUBTOTAL(9,CQ3:CQ77) -> 2941262.3 | CS1: =SUBTOTAL(9,CS3:CS77) -> 2972515.6 | CU1: =SUBTOTAL(9,CU3:CU77) -> 2652810 | CW1: =SUBTOTAL(9,CW3:CW77) -> 3142704.1 | CY1: =SUBTOTAL(9,CY3:CY77) -> 3248730.9 | DA1: =SUBTOTAL(9,DA3:DA77) -> 3015870.1 | DC1: =SUBTOTAL(9,DC3:DC77) -> 3073794.5 | DE1: =SUBTOTAL(9,DE3:DE77) -> 3013723.2 | DG1: =SUBTOTAL(9,DG3:DG77) -> 3324222 | DI1: =SUBTOTAL(9,DI3:DI77) -> 3245433.6 | DK1: =SUBTOTAL(9,DK3:DK77) -> 3019464.3 | DM1: =SUBTOTAL(9,DM3:DM77) -> 2978887.8 | DO1: =SUBTOTAL(9,DO3:DO77) -> 3113776 | DQ1: =SUBTOTAL(9,DQ3:DQ77) -> 3115473.4 | DS1: =SUBTOTAL(9,DS3:DS77) -> 3115828 | DT1: =SUM(F1:DS1) -> 1.6208924e+08
A2: Resource ID | B2: Family | C2: Brand | D2: Concat (ID/BRAND) | E2: Resource ID % Brand | F2: Aug FY26 - BRAND TOTAL | G2: Aug FY26 - RESOURCE ID QTY | H2: Sep FY26 - BRAND TOTAL | I2: Sep FY26 - Resource ID QTY | J2: Oct FY26 - BRAND TOTAL | K2: Oct FY26 - Resource ID QTY | L2: Nov FY26 - BRAND TOTAL | M2: Nov FY26 - Resource ID QTY | N2: Dec FY26 - BRAND TOTAL | O2: Dec FY26 - Resource ID QTY | P2: Jan FY26 - BRAND TOTAL | Q2: Jan FY26 - Resource ID QTY | R2: Feb FY26 - BRAND TOTAL | S2: Feb FY26 - Resource ID QTY | T2: Mar FY26 - BRAND TOTAL | U2: Mar FY26 - Resource ID QTY | V2: Apr FY26 - BRAND TOTAL | W2: Apr FY26 - Resource ID QTY | X2: May FY26 - BRAND TOTAL | Y2: May FY26 - Resource ID QTY | Z2: Jun FY26 - BRAND TOTAL | AA2: Jun FY26 - Resource ID QTY | AB2: Jul FY27 - BRAND TOTAL | AC2: Jul FY27 - Resource ID QTY | AD2: Aug FY27 - BRAND TOTAL | AE2: Aug FY27 - Resource ID QTY | AF2: Sep FY27 - BRAND TOTAL | AG2: Sep FY27 - Resource ID QTY | AH2: Oct FY27 - BRAND TOTAL | AI2: Oct FY27 - Resource ID QTY | AJ2: Nov FY27 - BRAND TOTAL | AK2: Nov FY27 - Resource ID QTY | AL2: Dec FY27 - BRAND TOTAL | AM2: Dec FY27 - Resource ID QTY | AN2: Jan FY27 - BRAND TOTAL | AO2: Jan FY27 - Resource ID QTY | AP2: Feb FY27 - BRAND TOTAL | AQ2: Feb FY27 - Resource ID QTY | AR2: Mar FY27 - BRAND TOTAL | AS2: Mar FY27 - Resource ID QTY | AT2: Apr FY27 - BRAND TOTAL | AU2: Apr FY27 - Resource ID QTY | AV2: May FY27 - BRAND TOTAL | AW2: May FY27 - Resource ID QTY | AX2: Jun FY27 - BRAND TOTAL | AY2: Jun FY27 - Resource ID QTY | AZ2: Jul FY28 - BRAND TOTAL | BA2: Jul FY28 - Resource ID QTY | BB2: Aug FY28 - BRAND TOTAL | BC2: Aug FY28 - Resource ID QTY | BD2: Sep FY28 - BRAND TOTAL | BE2: Sep FY28 - Resource ID QTY | BF2: Oct FY28 - BRAND TOTAL | BG2: Oct FY28 - Resource ID QTY | BH2: Nov FY28 - BRAND TOTAL | BI2: Nov FY28 - Resource ID QTY | BJ2: Dec FY28 - BRAND TOTAL | BK2: Dec FY28 - Resource ID QTY | BL2: Jan FY28 - BRAND TOTAL | BM2: Jan FY28 - Resource ID QTY | BN2: Feb FY28 - BRAND TOTAL | BO2: Feb FY28 - Resource ID QTY | BP2: Mar FY28 - BRAND TOTAL | BQ2: Mar FY28 - Resource ID QTY | BR2: Apr FY28 - BRAND TOTAL | BS2: Apr FY28 - Resource ID QTY | BT2: May FY28 - BRAND TOTAL | BU2: May FY28 - Resource ID QTY | BV2: Jun FY28 - BRAND TOTAL | BW2: Jun FY28 - Resource ID QTY | BX2: Jul FY29 - BRAND TOTAL | BY2: Jul FY29 - Resource ID QTY | BZ2: Aug FY29 - BRAND TOTAL | CA2: Aug FY29 - Resource ID QTY | CB2: Sep FY29 - BRAND TOTAL | CC2: Sep FY29 - Resource ID QTY | CD2: Oct FY29 - BRAND TOTAL | CE2: Oct FY29 - Resource ID QTY | CF2: Nov FY29 - BRAND TOTAL | CG2: Nov FY29 - Resource ID QTY | CH2: Dec FY29 - BRAND TOTAL | CI2: Dec FY29 - Resource ID QTY | CJ2: Jan FY29 - BRAND TOTAL | CK2: Jan FY29 - Resource ID QTY | CL2: Feb FY29 - BRAND TOTAL | CM2: Feb FY29 - Resource ID QTY | CN2: Mar FY29 - BRAND TOTAL | CO2: Mar FY29 - Resource ID QTY | CP2: Apr FY29 - BRAND TOTAL | CQ2: Apr FY29 - Resource ID QTY | CR2: May FY29 - BRAND TOTAL | CS2: May FY29 - Resource ID QTY | CT2: Jun FY29 - BRAND TOTAL | CU2: Jun FY29 - Resource ID QTY | CV2: Jul FY30 - BRAND TOTAL | CW2: Jul FY30 - Resource ID QTY | CX2: Aug FY30 - BRAND TOTAL | CY2: Aug FY30 - Resource ID QTY | CZ2: Sep FY30 - BRAND TOTAL | DA2: Sep FY30 - Resource ID QTY | DB2: Oct FY30 - BRAND TOTAL | DC2: Oct FY30 - Resource ID QTY | DD2: Nov FY30 - BRAND TOTAL | DE2: Nov FY30 - Resource ID QTY | DF2: Dec FY30 - BRAND TOTAL | DG2: Dec FY30 - Resource ID QTY | DH2: Jan FY30 - BRAND TOTAL | DI2: Jan FY30 - Resource ID QTY | DJ2: Feb FY30 - BRAND TOTAL | DK2: Feb FY30 - Resource ID QTY | DL2: Mar FY30 - BRAND TOTAL | DM2: Mar FY30 - Resource ID QTY | DN2: Apr FY30 - BRAND TOTAL | DO2: Apr FY30 - Resource ID QTY | DP2: May FY30 - BRAND TOTAL | DQ2: May FY30 - Resource ID QTY | DR2: Jun FY30 - BRAND TOTAL | DS2: Jun FY30 - Resource ID QTY
A3: A00A | B3: CSI | C3: BRITE TIP | D3: =_xlfn.CONCAT(A3,C3) -> A00ABRITE TIP | E3: 0.26277528 | F3: =SUMIF('5 Year Supply Plan'!A:A,'JZ_BRAND SPLITS'!C3,'5 Year Supply Plan'!H:H) -> 159148 | G3: =F3*E3 -> 41820.16 | H3: =SUMIF('5 Year Supply Plan'!A:A,'JZ_BRAND SPLITS'!C3,'5 Year Supply Plan'!I:I) -> 155459 | I3: =H3*E3 -> 40850.782 | J3: =SUMIF('5 Year Supply Plan'!A:A,'JZ_BRAND SPLITS'!C3,'5 Year Supply Plan'!J:J) -> 128367 | K3: =J3*E3 -> 33731.674 | L3: =SUMIF('5 Year Supply Plan'!A:A,'JZ_BRAND SPLITS'!C3,'5 Year Supply Plan'!K:K) -> 95000 | M3: =L3*E3 -> 24963.652 | N3: =SUMIF('5 Year Supply Plan'!A:A,'JZ_BRAND SPLITS'!C3,'5 Year Supply Plan'!L:L) -> 60740 | O3: =N3*E3 -> 15960.971 | P3: =SUMIF('5 Year Supply Plan'!A:A,'JZ_BRAND SPLITS'!C3,'5 Year Supply Plan'!M:M) -> 80000 | Q3: =P3*E3 -> 21022.022 | R3: =SUMIF('5 Year Supply Plan'!A:A,'JZ_BRAND SPLITS'!C3,'5 Year Supply Plan'!N:N) -> 95000 | S3: =R3*E3 -> 24963.652 | T3: =SUMIF('5 Year Supply Plan'!A:A,'JZ_BRAND SPLITS'!C3,'5 Year Supply Plan'!O:O) -> 95000 | U3: =T3*E3 -> 24963.652 | V3: =SUMIF('5 Year Supply Plan'!A:A,'JZ_BRAND SPLITS'!C3,'5 Year Supply Plan'!P:P) -> 95000 | W3: =V3*E3 -> 24963.652 | X3: =SUMIF('5 Year Supply Plan'!A:A,'JZ_BRAND SPLITS'!C3,'5 Year Supply Plan'!Q:Q) -> 95000 | Y3: =X3*E3 -> 24963.652 | Z3: =SUMIF('5 Year Supply Plan'!A:A,'JZ_BRAND SPLITS'!C3,'5 Year Supply Plan'!R:R) -> 100000 | AA3: =Z3*E3 -> 26277.528 | AB3: =SUMIF('5 Year Supply Plan'!A:A,'JZ_BRAND SPLITS'!C3,'5 Year Supply Plan'!S:S) -> 108680 | AC3: =AB3*E3 -> 28558.417 | AD3: =SUMIF('5 Year Supply Plan'!A:A,'JZ_BRAND SPLITS'!C3,'5 Year Supply Plan'!T:T) -> 108509 | AE3: =AD3*E3 -> 28513.483 | AF3: =SUMIF('5 Year Supply Plan'!A:A,'JZ_BRAND SPLITS'!C3,'5 Year Supply Plan'!U:U) -> 105148 | AG3: =AF3*E3 -> 27630.295 | AH3: =SUMIF('5 Year Supply Plan'!A:A,'JZ_BRAND SPLITS'!C3,'5 Year Supply Plan'!V:V) -> 108298 | AI3: =AH3*E3 -> 28458.037 | AJ3: =SUMIF('5 Year Supply Plan'!A:A,'JZ_BRAND SPLITS'!C3,'5 Year Supply Plan'!W:W) -> 101096 | AK3: =E3*AJ3 -> 26565.53 | AL3: =SUMIF('5 Year Supply Plan'!A:A,'JZ_BRAND SPLITS'!C3,'5 Year Supply Plan'!X:X) -> 106931 | AM3: =AL3*E3 -> 28098.824 | AN3: =SUMIF('5 Year Supply Plan'!A:A,'JZ_BRAND SPLITS'!C3,'5 Year Supply Plan'!Y:Y) -> 102807 | AO3: =AN3*E3 -> 27015.138 | AP3: =SUMIF('5 Year Supply Plan'!A:A,'JZ_BRAND SPLITS'!C3,'5 Year Supply Plan'!Z:Z) -> 89522 | AQ3: =AP3*E3 -> 23524.169 | AR3: =SUMIF('5 Year Supply Plan'!A:A,'JZ_BRAND SPLITS'!C3,'5 Year Supply Plan'!AA:AA) -> 102972 | AS3: =AR3*E3 -> 27058.496 | AT3: =SUMIF('5 Year Supply Plan'!A:A,'JZ_BRAND SPLITS'!C3,'5 Year Supply Plan'!AB:AB) -> 116923 | AU3: =AT3*E3 -> 30724.474 | AV3: =SUMIF('5 Year Supply Plan'!A:A,'JZ_BRAND SPLITS'!C3,'5 Year Supply Plan'!AC:AC) -> 105515 | AW3: =AV3*E3 -> 27726.734 | AX3: =SUMIF('5 Year Supply Plan'!A:A,'JZ_BRAND SPLITS'!C3,'5 Year Supply Plan'!AD:AD) -> 91383 | AY3: =AX3*E3 -> 24013.193 | AZ3: =SUMIF('5 Year Supply Plan'!A:A,'JZ_BRAND SPLITS'!C3,'5 Year Supply Plan'!AE:AE) -> 111801 | BA3: =AZ3*E3 -> 29378.539 | BB3: =SUMIF('5 Year Supply Plan'!A:A,'JZ_BRAND SPLITS'!C3,'5 Year Supply Plan'!AF:AF) -> 111595 | BC3: =BB3*E3 -> 29324.407 | BD3: =SUMIF('5 Year Supply Plan'!A:A,'JZ_BRAND SPLITS'!C3,'5 Year Supply Plan'!AG:AG) -> 108097 | BE3: =BD3*E3 -> 28405.219 | BF3: =SUMIF('5 Year Supply Plan'!A:A,'JZ_BRAND SPLITS'!C3,'5 Year Supply Plan'!AH:AH) -> 111224 | BG3: =BF3*E3 -> 29226.918 | BH3: =SUMIF('5 Year Supply Plan'!A:A,'JZ_BRAND SPLITS'!C3,'5 Year Supply Plan'!AI:AI) -> 103927 | BI3: =BH3*E3 -> 27309.447 | BJ3: =SUMIF('5 Year Supply Plan'!A:A,'JZ_BRAND SPLITS'!C3,'5 Year Supply Plan'!AJ:AJ) -> 110058 | BK3: =BJ3*E3 -> 28920.522 | BL3: =SUMIF('5 Year Supply Plan'!A:A,'JZ_BRAND SPLITS'!C3,'5 Year Supply Plan'!AK:AK) -> 105845 | BM3: =BL3*E3 -> 27813.45 | BN3: =SUMIF('5 Year Supply Plan'!A:A,'JZ_BRAND SPLITS'!C3,'5 Year Supply Plan'!AL:AL) -> 92075 | BO3: =BN3*E3 -> 24195.034 | BP3: =SUMIF('5 Year Supply Plan'!A:A,'JZ_BRAND SPLITS'!C3,'5 Year Supply Plan'!AM:AM) -> 106215 | BQ3: =BP3*E3 -> 27910.676 | BR3: =SUMIF('5 Year Supply Plan'!A:A,'JZ_BRAND SPLITS'!C3,'5 Year Supply Plan'!AN:AN) -> 121018 | BS3: =BR3*E3 -> 31800.539 | BT3: =SUMIF('5 Year Supply Plan'!A:A,'JZ_BRAND SPLITS'!C3,'5 Year Supply Plan'!AO:AO) -> 109939 | BU3: =BT3*E3 -> 28889.252 | BV3: =SUMIF('5 Year Supply Plan'!A:A,'JZ_BRAND SPLITS'!C3,'5 Year Supply Plan'!AP:AP) -> 95222 | BW3: =BV3*E3 -> 25021.988 | BX3: =SUMIF('5 Year Supply Plan'!A:A,'JZ_BRAND SPLITS'!C3,'5 Year Supply Plan'!AQ:AQ) -> 116566 | BY3: =BX3*E3 -> 30630.663 | BZ3: =SUMIF('5 Year Supply Plan'!A:A,'JZ_BRAND SPLITS'!C3,'5 Year Supply Plan'!AR:AR) -> 116333 | CA3: =BZ3*E3 -> 30569.437 | CB3: =SUMIF('5 Year Supply Plan'!A:A,'JZ_BRAND SPLITS'!C3,'5 Year Supply Plan'!AS:AS) -> 112657 | CC3: =CB3*E3 -> 29603.475 | CD3: =SUMIF('5 Year Supply Plan'!A:A,'JZ_BRAND SPLITS'!C3,'5 Year Supply Plan'!AT:AT) -> 115835 | CE3: =CD3*E3 -> 30438.575 | CF3: =SUMIF('5 Year Supply Plan'!A:A,'JZ_BRAND SPLITS'!C3,'5 Year Supply Plan'!AU:AU) -> 108309 | CG3: =CF3*E3 -> 28460.928 | CH3: =SUMIF('5 Year Supply Plan'!A:A,'JZ_BRAND SPLITS'!C3,'5 Year Supply Plan'!AV:AV) -> 114793 | CI3: =CH3*E3 -> 30164.763 | CJ3: =SUMIF('5 Year Supply Plan'!A:A,'JZ_BRAND SPLITS'!C3,'5 Year Supply Plan'!AW:AW) -> 110416 | CK3: =CJ3*E3 -> 29014.595 | CL3: =SUMIF('5 Year Supply Plan'!A:A,'JZ_BRAND SPLITS'!C3,'5 Year Supply Plan'!AX:AX) -> 96042 | CM3: =CL3*E3 -> 25237.463 | CN3: =SUMIF('5 Year Supply Plan'!A:A,'JZ_BRAND SPLITS'!C3,'5 Year Supply Plan'!AY:AY) -> 110495 | CO3: =CN3*E3 -> 29035.355 | CP3: =SUMIF('5 Year Supply Plan'!A:A,'JZ_BRAND SPLITS'!C3,'5 Year Supply Plan'!AZ:AZ) -> 125741 | CQ3: =CP3*E3 -> 33041.627 | CR3: =SUMIF('5 Year Supply Plan'!A:A,'JZ_BRAND SPLITS'!C3,'5 Year Supply Plan'!BA:BA) -> 114320 | CS3: =CR3*E3 -> 30040.47 | CT3: =SUMIF('5 Year Supply Plan'!A:A,'JZ_BRAND SPLITS'!C3,'5 Year Supply Plan'!BB:BB) -> 98918 | CU3: =CT3*E3 -> 25993.205 | CV3: =SUMIF('5 Year Supply Plan'!A:A,'JZ_BRAND SPLITS'!C3,'5 Year Supply Plan'!BC:BC) -> 121156 | CW3: =CV3*E3 -> 31836.802 | CX3: =SUMIF('5 Year Supply Plan'!A:A,'JZ_BRAND SPLITS'!C3,'5 Year Supply Plan'!BD:BD) -> 120888 | CY3: =CX3*E3 -> 31766.378 | CZ3: =SUMIF('5 Year Supply Plan'!A:A,'JZ_BRAND SPLITS'!C3,'5 Year Supply Plan'!BE:BE) -> 117018 | DA3: =CZ3*E3 -> 30749.438 | DB3: =SUMIF('5 Year Supply Plan'!A:A,'JZ_BRAND SPLITS'!C3,'5 Year Supply Plan'!BF:BF) -> 120215 | DC3: =DB3*E3 -> 31589.53 | DD3: =SUMIF('5 Year Supply Plan'!A:A,'JZ_BRAND SPLITS'!C3,'5 Year Supply Plan'!BG:BG) -> 112512 | DE3: =DD3*E3 -> 29565.372 | DF3: =SUMIF('5 Year Supply Plan'!A:A,'JZ_BRAND SPLITS'!C3,'5 Year Supply Plan'!BH:BH) -> 119373 | DG3: =DF3*E3 -> 31368.274 | DH3: =SUMIF('5 Year Supply Plan'!A:A,'JZ_BRAND SPLITS'!C3,'5 Year Supply Plan'!BI:BI) -> 114863 | DI3: =DH3*E3 -> 30183.157 | DJ3: =SUMIF('5 Year Supply Plan'!A:A,'JZ_BRAND SPLITS'!C3,'5 Year Supply Plan'!BJ:BJ) -> 99895 | DK3: =DJ3*E3 -> 26249.937 | DL3: =SUMIF('5 Year Supply Plan'!A:A,'JZ_BRAND SPLITS'!C3,'5 Year Supply Plan'!BK:BK) -> 103796 | DM3: =DL3*E3 -> 27275.023 | DN3: =SUMIF('5 Year Supply Plan'!A:A,'JZ_BRAND SPLITS'!C3,'5 Year Supply Plan'!BL:BL) -> 115239 | DO3: =DN3*E3 -> 30281.961 | DP3: =SUMIF('5 Year Supply Plan'!A:A,'JZ_BRAND SPLITS'!C3,'5 Year Supply Plan'!BM:BM) -> 113570 | DQ3: =DP3*E3 -> 29843.389 | DR3: =SUMIF('5 Year Supply Plan'!A:A,'JZ_BRAND SPLITS'!C3,'5 Year Supply Plan'!BN:BN) -> 113570 | DS3: =DR3*E3 -> 29843.389 | DT3: =DS3+DQ3+DO3+DM3+DK3+DI3+DG3+DE3+DC3+DA3+CY3+CW3+CU3+CS3+CQ3+CO3+CM3+CK3+CI3+CG3+CE3+CC3+CA3+BY3+BW3+BU3+BS3+BQ3+BO3+BM3+BK3+BI3+BG3+BE3+BC3+BA3+AY3+AW3+AU3+AS3+AQ3+AO3+AM3+AK3+AI3+AG3+AE3+AC3+AA3+Y3+W3+U3+S3+Q3+O3+M3+K3+I3+G3 -> 1683347.4 | DU3: =SUMIF('5 Year Supply Plan'!A:A,'JZ_BRAND SPLITS'!C3,'5 Year Supply Plan'!BO:BO) -> 6406034
A4: A00A | B4: CSI | C4: LONG SHEATH | D4: =_xlfn.CONCAT(A4,C4) -> A00ALONG SHEATH | E4: 1 | F4: =SUMIF('5 Year Supply Plan'!A:A,'JZ_BRAND SPLITS'!C4,'5 Year Supply Plan'!H:H) -> 3774.7332 | G4: =F4*E4 -> 3774.7332 | H4: =SUMIF('5 Year Supply Plan'!A:A,'JZ_BRAND SPLITS'!C4,'5 Year Supply Plan'!I:I) -> 1296.9573 | I4: =H4*E4 -> 1296.9573 | J4: =SUMIF('5 Year Supply Plan'!A:A,'JZ_BRAND SPLITS'!C4,'5 Year Supply Plan'!J:J) -> 1045.3728 | K4: =J4*E4 -> 1045.3728 | L4: =SUMIF('5 Year Supply Plan'!A:A,'JZ_BRAND SPLITS'!C4,'5 Year Supply Plan'!K:K) -> 946 | M4: =L4*E4 -> 946 | N4: =SUMIF('5 Year Supply Plan'!A:A,'JZ_BRAND SPLITS'!C4,'5 Year Supply Plan'!L:L) -> 905 | O4: =N4*E4 -> 905 | P4: =SUMIF('5 Year Supply Plan'!A:A,'JZ_BRAND SPLITS'!C4,'5 Year Supply Plan'!M:M) -> 1062 | Q4: =P4*E4 -> 1062 | R4: =SUMIF('5 Year Supply Plan'!A:A,'JZ_BRAND SPLITS'!C4,'5 Year Supply Plan'!N:N) -> 1039 | S4: =R4*E4 -> 1039 | T4: =SUMIF('5 Year Supply Plan'!A:A,'JZ_BRAND SPLITS'!C4,'5 Year Supply Plan'!O:O) -> 987 | U4: =T4*E4 -> 987 | V4: =SUMIF('5 Year Supply Plan'!A:A,'JZ_BRAND SPLITS'!C4,'5 Year Supply Plan'!P:P) -> 928 | W4: =V4*E4 -> 928 | X4: =SUMIF('5 Year Supply Plan'!A:A,'JZ_BRAND SPLITS'!C4,'5 Year Supply Plan'!Q:Q) -> 1008 | Y4: =X4*E4 -> 1008 | Z4: =SUMIF('5 Year Supply Plan'!A:A,'JZ_BRAND SPLITS'!C4,'5 Year Supply Plan'!R:R) -> 1053 | AA4: =Z4*E4 -> 1053 | AB4: =SUMIF('5 Year Supply Plan'!A:A,'JZ_BRAND SPLITS'!C4,'5 Year Supply Plan'!S:S) -> 1226 | AC4: =AB4*E4 -> 1226 | AD4: =SUMIF('5 Year Supply Plan'!A:A,'JZ_BRAND SPLITS'!C4,'5 Year Supply Plan'!T:T) -> 1229 | AE4: =AD4*E4 -> 1229 | AF4: =SUMIF('5 Year Supply Plan'!A:A,'JZ_BRAND SPLITS'!C4,'5 Year Supply Plan'!U:U) -> 1120 | AG4: =AF4*E4 -> 1120 | AH4: =SUMIF('5 Year Supply Plan'!A:A,'JZ_BRAND SPLITS'!C4,'5 Year Supply Plan'!V:V) -> 1193 | AI4: =AH4*E4 -> 1193 | AJ4: =SUMIF('5 Year Supply Plan'!A:A,'JZ_BRAND SPLITS'!C4,'5 Year Supply Plan'!W:W) -> 1141 | AK4: =E4*AJ4 -> 1141 | AL4: =SUMIF('5 Year Supply Plan'!A:A,'JZ_BRAND SPLITS'!C4,'5 Year Supply Plan'!X:X) -> 1263 | AM4: =AL4*E4 -> 1263 | AN4: =SUMIF('5 Year Supply Plan'!A:A,'JZ_BRAND SPLITS'!C4,'5 Year Supply Plan'!Y:Y) -> 1255 | AO4: =AN4*E4 -> 1255 | AP4: =SUMIF('5 Year Supply Plan'!A:A,'JZ_BRAND SPLITS'!C4,'5 Year Supply Plan'!Z:Z) -> 1154 | AQ4: =AP4*E4 -> 1154 | AR4: =SUMIF('5 Year Supply Plan'!A:A,'JZ_BRAND SPLITS'!C4,'5 Year Supply Plan'!AA:AA) -> 1140 | AS4: =AR4*E4 -> 1140 | AT4: =SUMIF('5 Year Supply Plan'!A:A,'JZ_BRAND SPLITS'!C4,'5 Year Supply Plan'!AB:AB) -> 1150 | AU4: =AT4*E4 -> 1150 | AV4: =SUMIF('5 Year Supply Plan'!A:A,'JZ_BRAND SPLITS'!C4,'5 Year Supply Plan'!AC:AC) -> 1182 | AW4: =AV4*E4 -> 1182 | AX4: =SUMIF('5 Year Supply Plan'!A:A,'JZ_BRAND SPLITS'!C4,'5 Year Supply Plan'!AD:AD) -> 1053 | AY4: =AX4*E4 -> 1053 | AZ4: =SUMIF('5 Year Supply Plan'!A:A,'JZ_BRAND SPLITS'!C4,'5 Year Supply Plan'!AE:AE) -> 1229 | BA4: =AZ4*E4 -> 1229 | BB4: =SUMIF('5 Year Supply Plan'!A:A,'JZ_BRAND SPLITS'!C4,'5 Year Supply Plan'!AF:AF) -> 1229 | BC4: =BB4*E4 -> 1229 | BD4: =SUMIF('5 Year Supply Plan'!A:A,'JZ_BRAND SPLITS'!C4,'5 Year Supply Plan'!AG:AG) -> 1123 | BE4: =BD4*E4 -> 1123 | BF4: =SUMIF('5 Year Supply Plan'!A:A,'JZ_BRAND SPLITS'!C4,'5 Year Supply Plan'!AH:AH) -> 1194 | BG4: =BF4*E4 -> 1194 | BH4: =SUMIF('5 Year Supply Plan'!A:A,'JZ_BRAND SPLITS'!C4,'5 Year Supply Plan'!AI:AI) -> 1141 | BI4: =BH4*E4 -> 1141 | BJ4: =SUMIF('5 Year Supply Plan'!A:A,'JZ_BRAND SPLITS'!C4,'5 Year Supply Plan'!AJ:AJ) -> 1265 | BK4: =BJ4*E4 -> 1265 | BL4: =SUMIF('5 Year Supply Plan'!A:A,'JZ_BRAND SPLITS'!C4,'5 Year Supply Plan'!AK:AK) -> 1255 | BM4: =BL4*E4 -> 1255 | BN4: =SUMIF('5 Year Supply Plan'!A:A,'JZ_BRAND SPLITS'!C4,'5 Year Supply Plan'!AL:AL) -> 1152 | BO4: =BN4*E4 -> 1152 | BP4: =SUMIF('5 Year Supply Plan'!A:A,'JZ_BRAND SPLITS'!C4,'5 Year Supply Plan'!AM:AM) -> 1149 | BQ4: =BP4*E4 -> 1149 | BR4: =SUMIF('5 Year Supply Plan'!A:A,'JZ_BRAND SPLITS'!C4,'5 Year Supply Plan'!AN:AN) -> 1173 | BS4: =BR4*E4 -> 1173 | BT4: =SUMIF('5 Year Supply Plan'!A:A,'JZ_BRAND SPLITS'!C4,'5 Year Supply Plan'!AO:AO) -> 1204 | BU4: =BT4*E4 -> 1204 | BV4: =SUMIF('5 Year Supply Plan'!A:A,'JZ_BRAND SPLITS'!C4,'5 Year Supply Plan'!AP:AP) -> 1071 | BW4: =BV4*E4 -> 1071 | BX4: =SUMIF('5 Year Supply Plan'!A:A,'JZ_BRAND SPLITS'!C4,'5 Year Supply Plan'!AQ:AQ) -> 1256 | BY4: =BX4*E4 -> 1256 | BZ4: =SUMIF('5 Year Supply Plan'!A:A,'JZ_BRAND SPLITS'!C4,'5 Year Supply Plan'!AR:AR) -> 1251 | CA4: =BZ4*E4 -> 1251 | CB4: =SUMIF('5 Year Supply Plan'!A:A,'JZ_BRAND SPLITS'!C4,'5 Year Supply Plan'!AS:AS) -> 1144 | CC4: =CB4*E4 -> 1144 | CD4: =SUMIF('5 Year Supply Plan'!A:A,'JZ_BRAND SPLITS'!C4,'5 Year Supply Plan'!AT:AT) -> 1215 | CE4: =CD4*E4 -> 1215 | CF4: =SUMIF('5 Year Supply Plan'!A:A,'JZ_BRAND SPLITS'!C4,'5 Year Supply Plan'!AU:AU) -> 1162 | CG4: =CF4*E4 -> 1162 | CH4: =SUMIF('5 Year Supply Plan'!A:A,'JZ_BRAND SPLITS'!C4,'5 Year Supply Plan'!AV:AV) -> 1290 | CI4: =CH4*E4 -> 1290 | CJ4: =SUMIF('5 Year Supply Plan'!A:A,'JZ_BRAND SPLITS'!C4,'5 Year Supply Plan'!AW:AW) -> 1279 | CK4: =CJ4*E4 -> 1279 | CL4: =SUMIF('5 Year Supply Plan'!A:A,'JZ_BRAND SPLITS'!C4,'5 Year Supply Plan'!AX:AX) -> 1172 | CM4: =CL4*E4 -> 1172 | CN4: =SUMIF('5 Year Supply Plan'!A:A,'JZ_BRAND SPLITS'!C4,'5 Year Supply Plan'!AY:AY) -> 1167 | CO4: =CN4*E4 -> 1167 | CP4: =SUMIF('5 Year Supply Plan'!A:A,'JZ_BRAND SPLITS'!C4,'5 Year Supply Plan'!AZ:AZ) -> 1190 | CQ4: =CP4*E4 -> 1190 | CR4: =SUMIF('5 Year Supply Plan'!A:A,'JZ_BRAND SPLITS'!C4,'5 Year Supply Plan'!BA:BA) -> 1220 | CS4: =CR4*E4 -> 1220 | CT4: =SUMIF('5 Year Supply Plan'!A:A,'JZ_BRAND SPLITS'!C4,'5 Year Supply Plan'!BB:BB) -> 1087 | CU4: =CT4*E4 -> 1087 | CV4: =SUMIF('5 Year Supply Plan'!A:A,'JZ_BRAND SPLITS'!C4,'5 Year Supply Plan'!BC:BC) -> 1271 | CW4: =CV4*E4 -> 1271 | CX4: =SUMIF('5 Year Supply Plan'!A:A,'JZ_BRAND SPLITS'!C4,'5 Year Supply Plan'!BD:BD) -> 1271 | CY4: =CX4*E4 -> 1271 | CZ4: =SUMIF('5 Year Supply Plan'!A:A,'JZ_BRAND SPLITS'!C4,'5 Year Supply Plan'!BE:BE) -> 1159 | DA4: =CZ4*E4 -> 1159 | DB4: =SUMIF('5 Year Supply Plan'!A:A,'JZ_BRAND SPLITS'!C4,'5 Year Supply Plan'!BF:BF) -> 1231 | DC4: =DB4*E4 -> 1231 | DD4: =SUMIF('5 Year Supply Plan'!A:A,'JZ_BRAND SPLITS'!C4,'5 Year Supply Plan'!BG:BG) -> 1179 | DE4: =DD4*E4 -> 1179 | DF4: =SUMIF('5 Year Supply Plan'!A:A,'JZ_BRAND SPLITS'!C4,'5 Year Supply Plan'!BH:BH) -> 1308 | DG4: =DF4*E4 -> 1308 | DH4: =SUMIF('5 Year Supply Plan'!A:A,'JZ_BRAND SPLITS'!C4,'5 Year Supply Plan'!BI:BI) -> 1296 | DI4: =DH4*E4 -> 1296 | DJ4: =SUMIF('5 Year Supply Plan'!A:A,'JZ_BRAND SPLITS'!C4,'5 Year Supply Plan'!BJ:BJ) -> 1198 | DK4: =DJ4*E4 -> 1198 | DL4: =SUMIF('5 Year Supply Plan'!A:A,'JZ_BRAND SPLITS'!C4,'5 Year Supply Plan'!BK:BK) -> 1303 | DM4: =DL4*E4 -> 1303 | DN4: =SUMIF('5 Year Supply Plan'!A:A,'JZ_BRAND SPLITS'!C4,'5 Year Supply Plan'!BL:BL) -> 1491 | DO4: =DN4*E4 -> 1491 | DP4: =SUMIF('5 Year Supply Plan'!A:A,'JZ_BRAND SPLITS'!C4,'5 Year Supply Plan'!BM:BM) -> 1243.125 | DQ4: =DP4*E4 -> 1243.125 | DR4: =SUMIF('5 Year Supply Plan'!A:A,'JZ_BRAND SPLITS'!C4,'5 Year Supply Plan'!BN:BN) -> 1243.125 | DS4: =DR4*E4 -> 1243.125 | DT4: =DS4+DQ4+DO4+DM4+DK4+DI4+DG4+DE4+DC4+DA4+CY4+CW4+CU4+CS4+CQ4+CO4+CM4+CK4+CI4+CG4+CE4+CC4+CA4+BY4+BW4+BU4+BS4+BQ4+BO4+BM4+BK4+BI4+BG4+BE4+BC4+BA4+AY4+AW4+AU4+AS4+AQ4+AO4+AM4+AK4+AI4+AG4+AE4+AC4+AA4+Y4+W4+U4+S4+Q4+O4+M4+K4+I4+G4 -> 71962.313 | DU4: =SUMIF('5 Year Supply Plan'!A:A,'JZ_BRAND SPLITS'!C4,'5 Year Supply Plan'!BO:BO) -> 71962.313
